
WARNING: Dataset not found, nonexistent paths: ['D:\\custom_data\\test\\images']
Traceback (most recent call last):
  File "D:\pythonProject1\yolov5\train.py", line 626, in <module>
    main(opt)
  File "D:\pythonProject1\yolov5\train.py", line 523, in main
    train(opt.hyp, opt, device, callbacks)
  File "D:\pythonProject1\yolov5\train.py", line 88, in train
    loggers = Loggers(save_dir, weights, opt, hyp, LOGGER)  # loggers instance
  File "D:\pythonProject1\yolov5\utils\loggers\__init__.py", line 72, in __init__
    self.wandb = WandbLogger(self.opt, run_id)
  File "D:\pythonProject1\yolov5\utils\loggers\wandb\wandb_utils.py", line 180, in __init__
    self.data_dict = check_wandb_dataset(opt.data)
  File "D:\pythonProject1\yolov5\utils\loggers\wandb\wandb_utils.py", line 56, in check_wandb_dataset
    return check_dataset(data_file)
  File "D:\pythonProject1\yolov5\utils\general.py", line 412, in check_dataset
    raise Exception('Dataset not found.')
Exception: Dataset not found.